<?xml version="1.0" ?>
<sdf version="1.5">
  <world name="default">
    <!-- Ground -->
    <include>
      <uri>model://ground_plane</uri>
    </include>        
    <!-- A global light source -->
    <include>
      <uri>model://sun</uri>
    </include>

    <magnetic_field>.1 0 0</magnetic_field>
    
    <physics type='ode'>
      <max_step_size>0.001</max_step_size>
      <real_time_factor>1</real_time_factor>
      <real_time_update_rate>1000</real_time_update_rate>
      <gravity>0 0 -9.8</gravity>
    </physics>

    <!-- Rotary Inverted Pendulum -->
    <model name="rip">      
      <link name='base'>
        <pose>0 0 0 0 0 0</pose>
        <visual name="visual">
          <pose>0 0 .148 0 0 0</pose>
          <geometry>
            <cylinder>
              <radius>0.015</radius>
              <length>.297</length>
            </cylinder>
          </geometry>      
        </visual>
      </link>

      <joint name="base_joint" type="fixed">
        <parent>world</parent>
        <child>base</child>
        <pose>0 0 0 0 0 0</pose>
      </joint>

      <link name='arm'>
        <pose>0 0 .3 0 0 0</pose>
        <gravity>true</gravity>
        <inertial>
          <mass>0.0395</mass>
          <inertia>
            <ixx>.000125</ixx>
            <iyy>.000125</iyy>
            <izz>.0000125</izz>
            <ixy>0</ixy>
            <ixz>0</ixz>
            <iyz>0</iyz>
          </inertia>
          <pose>.09 0 0 0 0 0</pose>
        </inertial>
        <visual name="visual">
          <pose>.095 0 0 0 0 0</pose>
          <geometry>
            <box>
              <size>.200 .020 .005</size>
            </box>
          </geometry>      
        </visual>
        <collision name="collision">
          <pose>.095 0 0 0 0 0</pose>
          <geometry>
            <box>
              <size>.200 .020 .005</size>
            </box>
          </geometry>      
        </collision>

        <sensor name="contact_sensor" type="contact">
          <contact>
            <collision>collision</collision>
          </contact>
          <always_on>true</always_on>         
        </sensor>
      </link>

      <joint name="joint_1" type="revolute">
        <parent>base</parent>
        <child>arm</child>
        <axis>
          <xyz>0 0 1</xyz>
          <dynamics>
            <damping>0.00001</damping>
            <friction>0.000000</friction>
          </dynamics>
        </axis>        
      </joint>

      <link name='pendulum'>
        <pose>.2 0 .3 0 0 0</pose>
        <gravity>true</gravity>
        <inertial>
          <mass>0.192</mass>
          <inertia>
            <ixx>.000866</ixx>
            <iyy>.000866</iyy>
            <izz>.0000866</izz>
            <ixy>0</ixy>
            <ixz>0</ixz>
            <iyz>0</iyz>
          </inertia>
          <pose>0 0 -.128 0 0 0</pose>
        </inertial>
        <visual name="visual">
          <pose>0 0 -.125 0 0 0</pose>
          <geometry>
            <cylinder>
             <radius>.005</radius>
             <length>.250</length>
            </cylinder>
          </geometry>      
        </visual>
        <sensor name="camera" type="camera">
          <pose>0 0 -.250 0 0 0</pose>          
          <camera>            
            <horizontal_fov>1.047</horizontal_fov>
            <image>
              <width>320</width>
              <height>240</height>
            </image>
            <clip>
              <near>0.1</near>
              <far>100</far>
            </clip>
          </camera>
          <always_on>1</always_on>
          <update_rate>30</update_rate>
          <visualize>false</visualize>
        </sensor>
        <sensor name="depth" type="depth">
          <pose>0 0 -.250 0 0 0</pose>          
          <camera>            
            <horizontal_fov>1.047</horizontal_fov>
            <image>
              <width>320</width>
              <height>240</height>
            </image>
            <clip>
              <near>0.1</near>
              <far>100</far>
            </clip>            
          </camera>
          <always_on>1</always_on>
          <update_rate>30</update_rate>
          <visualize>false</visualize>          
        </sensor>
        <sensor name="logical_camera" type="logical_camera">
          <pose>0 0 -.250 0 0 0</pose>          
          <logical_camera>            
            <horizontal_fov>1.047</horizontal_fov>
            <near>0.1</near>
            <far>100</far>          
            <aspect_ration>1</aspect_ration>  
          </logical_camera>
          <always_on>1</always_on>
          <update_rate>30</update_rate>
          <visualize>false</visualize>
        </sensor>
        <sensor name="laser" type="ray">
          <pose>0 0 -.250 0 0 0</pose>
          <ray>
            <scan>
              <horizontal>
                <samples>100</samples>
                <resolution>1</resolution>
                <min_angle>-0.5</min_angle>
                <max_angle>0.5</max_angle>
              </horizontal>
              <vertical>
                <samples>100</samples>
                <resolution>1</resolution>
                <min_angle>-0.5</min_angle>
                <max_angle>0.5</max_angle>
              </vertical>
            </scan>
            <range>
              <min>0.08</min>
              <max>100</max>
            </range>           
          </ray>
          <always_on>1</always_on>
          <update_rate>30</update_rate>
        </sensor>
        <sensor name="gpulaser" type="gpu_ray">
          <pose>0 0 -.250 0 0 0</pose>
          <ray>
            <scan>
              <horizontal>
                <samples>100</samples>
                <resolution>1</resolution>
                <min_angle>-0.5</min_angle>
                <max_angle>0.5</max_angle>
              </horizontal>
              <vertical>
                <samples>100</samples>
                <resolution>1</resolution>
                <min_angle>-0.5</min_angle>
                <max_angle>0.5</max_angle>
              </vertical>
            </scan>
            <range>
              <min>0.08</min>
              <max>100</max>
            </range>           
          </ray>
          <always_on>1</always_on>
          <update_rate>30</update_rate>
        </sensor>

        <sensor name="altimeter" type="altimeter">
          <pose>0 0 -.250 0 0 0</pose>
          <always_on>true</always_on>         
        </sensor>
        <sensor name="sonar" type="sonar">
          <pose>0 0 -.250 0 0 0</pose>
          <sonar>
            <min>0.1</min>
            <max>10</max>
            <radius>.25</radius>
          </sonar>
          <update_rate>30</update_rate>
          <always_on>true</always_on>
          <visualize>false</visualize>         
        </sensor>
        <sensor name="magnetometer" type="magnetometer">
          <pose>0 0 -.250 0 0 0</pose>
          <always_on>true</always_on>
          <update_rate>30</update_rate>       
        </sensor>
      </link>
   

      <joint name="joint_2" type="revolute">
        <parent>arm</parent>
        <child>pendulum</child>
        <axis>
          <xyz>1 0 0</xyz>
          <dynamics>
            <damping>0.00001</damping>
            <friction>0.000000</friction>
          </dynamics>
        </axis>
        <sensor name="force_torque" type="force_torque">
          <always_on>true</always_on>
          <update_rate>30</update_rate>
        </sensor>                 
      </joint>      
    </model>

    <!-- Put in some cylinders so the camera has something to look at -->
    <model name="post">
       <static>true</static>
       <link name="post1">
         <visual name="visual">
           <pose>3 0 0.5 0 0 0</pose>
           <geometry>
             <cylinder>
               <radius>0.05</radius>
               <length>1</length>
             </cylinder>
           </geometry>
           <material>
             <ambient>1 0 0 0</ambient>
           </material>
         </visual>
         <collision name="collision">
           <pose>3 0 0.5 0 0 0</pose>
           <geometry>
             <cylinder>
               <radius>0.05</radius>
               <length>1</length>
             </cylinder>
           </geometry>           
         </collision>         
       </link>
       <link name="post2">
         <visual name="visual">
           <pose>3 3 .5 0 0 0</pose>
           <geometry>
             <cylinder>
               <radius>0.05</radius>
               <length>1</length>
             </cylinder>
           </geometry>
           <material>
             <ambient>0 1 0 0</ambient>
           </material>
         </visual>
         <collision name="collision">
           <pose>3 0 0.5 0 0 0</pose>
           <geometry>
             <cylinder>
               <radius>0.05</radius>
               <length>1</length>
             </cylinder>
           </geometry>           
         </collision>      
       </link>
       <link name="post3">
         <visual name="visual">
           <pose>3.0 -3.0 0.5 0 0 0</pose>
           <geometry>
             <cylinder>
               <radius>0.05</radius>
               <length>1</length>
             </cylinder>
           </geometry>
           <material>
             <ambient>0 0 1 0</ambient>
           </material>
         </visual>
         <collision name="collision">
           <pose>3 0 0.5 0 0 0</pose>
           <geometry>
             <cylinder>
               <radius>0.05</radius>
               <length>1</length>
             </cylinder>
           </geometry>           
         </collision>         
       </link>
       <link name="post3">
         <visual name="visual">
           <pose>0 -0.15 0.25 0 0 0</pose>
           <geometry>
             <cylinder>
               <radius>0.015</radius>
               <length>.5</length>
             </cylinder>
           </geometry>
           <material>
             <ambient>0 0 0 0</ambient>
           </material>
         </visual>
         <collision name="collision">
           <pose>0 -0.15 0.25 0 0 0</pose>
           <geometry>
             <cylinder>
               <radius>0.015</radius>
               <length>.5</length>
             </cylinder>
           </geometry>           
         </collision>         
       </link>
    </model>

  </world>
</sdf>
